Workbook

Sheet รายงานลูกหนี้
A1: ชื่อลูกหนี้ | B1: สาขา | C1: ระยะเวลาเครดิต | D1: เลขที่ใบวางบิล | E1: วันที่วางบิลได้ | F1: วันที่จบ | G1: จำนวนเงิน | H1: วันครบกำหนด(Due Date) | I1: วันที่ปัจจุบัน | J1: กลุ่มอายุลูกหนี้ | K1: ตัวเลขวันช้า | L1: ชั้นลูกหนี้ (TFRS 9)
A2: 1ffd1b76f559a74aa8c6ebe473d24404afad7a1bb7ac8f9e019b6ec17993fe6d | B2: ลำปาง | C2: 7 | D2: 1526010007215 | E2: 46037 | F2: 46038 | G2: 2920 | H2: =E2+C2 -> 46044 | I2: 46253 | J2: =IF(K3<=0, "ชำระตรงเวลา", IF(K3<=30, "ค้างชำระ 1 - 30 วัน", IF(K3<=60, "ค้างชำระ 31 - 60 วัน", IF(K3<=90, "ค้างชำระ 61 - 90 วัน", "ค้างชำระเกิน 90 วัน")))) -> ชำระตรงเวลา | K2: =IF(OR(F2="",F2="(ว่าง)"), MAX(0,I1-H2), MAX(0,F2-H2)) -> 0 | L2: =IF(K2<=30, "ลูกหนี้ชั้นดี", IF(K2<=90, "ลูกหนี้เฝ้าติดตาม", "ลูกหนี้ด้อยคุณภาพ (NPL)")) -> ลูกหนี้ชั้นดี
A3: bffb4c8260b96f7a32415a51753355e53d31f418fb1ed184109d6d681a358817 | B3: ลำปาง | C3: 7 | D3: 1526010008847 | E3: 46041 | F3: 46042 | G3: 60 | H3: =E3+C3 -> 46048 | I3: =I2 -> 46253 | J3: =IF(K4<=0, "ชำระตรงเวลา", IF(K4<=30, "ค้างชำระ 1 - 30 วัน", IF(K4<=60, "ค้างชำระ 31 - 60 วัน", IF(K4<=90, "ค้างชำระ 61 - 90 วัน", "ค้างชำระเกิน 90 วัน")))) -> ค้างชำระ 1 - 30 วัน | K3: =IF(OR(F3="",F3="(ว่าง)"), MAX(0,I2-H3), MAX(0,F3-H3)) -> 0 | L3: =IF(K3<=30, "ลูกหนี้ชั้นดี", IF(K3<=90, "ลูกหนี้เฝ้าติดตาม", "ลูกหนี้ด้อยคุณภาพ (NPL)")) -> ลูกหนี้ชั้นดี
A4: f57f896561c9744b813a45d7559080a4a65523a63f3434d8b51daff767d9231f | B4: ลำพูน | C4: 7 | D4: 1326010005118 | E4: 46035 | F4: 46043 | G4: 825 | H4: =E4+C4 -> 46042 | I4: =I3 -> 46253 | J4: =IF(K5<=0, "ชำระตรงเวลา", IF(K5<=30, "ค้างชำระ 1 - 30 วัน", IF(K5<=60, "ค้างชำระ 31 - 60 วัน", IF(K5<=90, "ค้างชำระ 61 - 90 วัน", "ค้างชำระเกิน 90 วัน")))) -> ชำระตรงเวลา | K4: =IF(OR(F4="",F4="(ว่าง)"), MAX(0,I3-H4), MAX(0,F4-H4)) -> 1 | L4: =IF(K4<=30, "ลูกหนี้ชั้นดี", IF(K4<=90, "ลูกหนี้เฝ้าติดตาม", "ลูกหนี้ด้อยคุณภาพ (NPL)")) -> ลูกหนี้ชั้นดี
A5: 738e4c9a89f462bcca485657195e9a598fd42a9babb103493de6081512c10c19 | B5: ลำปาง | C5: 7 | D5: 1526010008618 | E5: 46042 | F5: 46045 | G5: 13825 | H5: =E5+C5 -> 46049 | I5: =I4 -> 46253 | J5: =IF(K6<=0, "ชำระตรงเวลา", IF(K6<=30, "ค้างชำระ 1 - 30 วัน", IF(K6<=60, "ค้างชำระ 31 - 60 วัน", IF(K6<=90, "ค้างชำระ 61 - 90 วัน", "ค้างชำระเกิน 90 วัน")))) -> ชำระตรงเวลา | K5: =IF(OR(F5="",F5="(ว่าง)"), MAX(0,I4-H5), MAX(0,F5-H5)) -> 0 | L5: =IF(K5<=30, "ลูกหนี้ชั้นดี", IF(K5<=90, "ลูกหนี้เฝ้าติดตาม", "ลูกหนี้ด้อยคุณภาพ (NPL)")) -> ลูกหนี้ชั้นดี
A6: 50ed86b5f35eb2271f958e9d1f331d0a9eeae7b50a10f8e3bd67368264b1e489 | B6: ฝาง | C6: 7 | D6: 1226010009416 | E6: 46043 | F6: 46050 | G6: 2075 | H6: =E6+C6 -> 46050 | I6: =I5 -> 46253 | J6: =IF(K7<=0, "ชำระตรงเวลา", IF(K7<=30, "ค้างชำระ 1 - 30 วัน", IF(K7<=60, "ค้างชำระ 31 - 60 วัน", IF(K7<=90, "ค้างชำระ 61 - 90 วัน", "ค้างชำระเกิน 90 วัน")))) -> ค้างชำระ 1 - 30 วัน | K6: =IF(OR(F6="",F6="(ว่าง)"), MAX(0,I5-H6), MAX(0,F6-H6)) -> 0 | L6: =IF(K6<=30, "ลูกหนี้ชั้นดี", IF(K6<=90, "ลูกหนี้เฝ้าติดตาม", "ลูกหนี้ด้อยคุณภาพ (NPL)")) -> ลูกหนี้ชั้นดี
A7: c07e4e324959006e76c15356ba0403db32c9bb122aef4882ebeaecc4eb47dde3 | B7: ลำปาง | C7: 30 | D7: 1526010009257 | E7: 46043 | F7: 46078 | G7: 6894 | H7: =E7+C7 -> 46073 | I7: =I6 -> 46253 | J7: =IF(K8<=0, "ชำระตรงเวลา", IF(K8<=30, "ค้างชำระ 1 - 30 วัน", IF(K8<=60, "ค้างชำระ 31 - 60 วัน", IF(K8<=90, "ค้างชำระ 61 - 90 วัน", "ค้างชำระเกิน 90 วัน")))) -> ชำระตรงเวลา | K7: =IF(OR(F7="",F7="(ว่าง)"), MAX(0,I6-H7), MAX(0,F7-H7)) -> 5 | L7: =IF(K7<=30, "ลูกหนี้ชั้นดี", IF(K7<=90, "ลูกหนี้เฝ้าติดตาม", "ลูกหนี้ด้อยคุณภาพ (NPL)")) -> ลูกหนี้ชั้นดี
A8: 07a3531a5a5dcc04dffc460ce464d6d9f55098d0e6a50ff21be397c2c4ecaa57 | B8: ลำปาง | C8: 7 | D8: 1526010008823 | E8: 46041 | F8: 46042 | G8: 390 | H8: =E8+C8 -> 46048 | I8: =I7 -> 46253 | J8: =IF(K9<=0, "ชำระตรงเวลา", IF(K9<=30, "ค้างชำระ 1 - 30 วัน", IF(K9<=60, "ค้างชำระ 31 - 60 วัน", IF(K9<=90, "ค้างชำระ 61 - 90 วัน", "ค้างชำระเกิน 90 วัน")))) -> ชำระตรงเวลา | K8: =IF(OR(F8="",F8="(ว่าง)"), MAX(0,I7-H8), MAX(0,F8-H8)) -> 0 | L8: =IF(K8<=30, "ลูกหนี้ชั้นดี", IF(K8<=90, "ลูกหนี้เฝ้าติดตาม", "ลูกหนี้ด้อยคุณภาพ (NPL)")) -> ลูกหนี้ชั้นดี
A9: 9c55cffff99073d4ebdef08e1a9c79a757143bf3ecc524033ef4ba8a53cdc5be | B9: ฝาง | C9: 7 | D9: 1226010009348 | E9: 46043 | F9: 46050 | G9: 2490 | H9: =E9+C9 -> 46050 | I9: =I8 -> 46253 | J9: =IF(K10<=0, "ชำระตรงเวลา", IF(K10<=30, "ค้างชำระ 1 - 30 วัน", IF(K10<=60, "ค้างชำระ 31 - 60 วัน", IF(K10<=90, "ค้างชำระ 61 - 90 วัน", "ค้างชำระเกิน 90 วัน")))) -> ค้างชำระ 1 - 30 วัน | K9: =IF(OR(F9="",F9="(ว่าง)"), MAX(0,I8-H9), MAX(0,F9-H9)) -> 0 | L9: =IF(K9<=30, "ลูกหนี้ชั้นดี", IF(K9<=90, "ลูกหนี้เฝ้าติดตาม", "ลูกหนี้ด้อยคุณภาพ (NPL)")) -> ลูกหนี้ชั้นดี
A10: 7914ce908cda19e741dd75c7b223b1857bf56c8de81c298d9da7eb0ed86efbb4 | B10: ลำปาง | C10: 7 | D10: 1526010009233 | E10: 46043 | F10: 46052 | G10: 5220 | H10: =E10+C10 -> 46050 | I10: =I9 -> 46253 | J10: =IF(K11<=0, "ชำระตรงเวลา", IF(K11<=30, "ค้างชำระ 1 - 30 วัน", IF(K11<=60, "ค้างชำระ 31 - 60 วัน", IF(K11<=90, "ค้างชำระ 61 - 90 วัน", "ค้างชำระเกิน 90 วัน")))) -> ค้างชำระ 1 - 30 วัน | K10: =IF(OR(F10="",F10="(ว่าง)"), MAX(0,I9-H10), MAX(0,F10-H10)) -> 2 | L10: =IF(K10<=30, "ลูกหนี้ชั้นดี", IF(K10<=90, "ลูกหนี้เฝ้าติดตาม", "ลูกหนี้ด้อยคุณภาพ (NPL)")) -> ลูกหนี้ชั้นดี
A11: 53a194ee08d0adb2cdd9813398d0613159cccdae90786745f4a4bb8f4e755008 | B11: ลำปาง | C11: 7 | D11: 1526010008748 | E11: 46042 | F11: 46051 | G11: 4454 | H11: =E11+C11 -> 46049 | I11: =I10 -> 46253 | J11: =IF(K12<=0, "ชำระตรงเวลา", IF(K12<=30, "ค้างชำระ 1 - 30 วัน", IF(K12<=60, "ค้างชำระ 31 - 60 วัน", IF(K12<=90, "ค้างชำระ 61 - 90 วัน", "ค้างชำระเกิน 90 วัน")))) -> ชำระตรงเวลา | K11: =IF(OR(F11="",F11="(ว่าง)"), MAX(0,I10-H11), MAX(0,F11-H11)) -> 2 | L11: =IF(K11<=30, "ลูกหนี้ชั้นดี", IF(K11<=90, "ลูกหนี้เฝ้าติดตาม", "ลูกหนี้ด้อยคุณภาพ (NPL)")) -> ลูกหนี้ชั้นดี
A12: 562f700bd959ed5df49e26454a52c3b2b2b722eaa328ce19b2f9f36cc0cd5314 | B12: ลำปาง | C12: 7 | D12: 1526010009189 | E12: 46044 | F12: 46044 | G12: 506 | H12: =E12+C12 -> 46051 | I12: =I11 -> 46253 | J12: =IF(K13<=0, "ชำระตรงเวลา", IF(K13<=30, "ค้างชำระ 1 - 30 วัน", IF(K13<=60, "ค้างชำระ 31 - 60 วัน", IF(K13<=90, "ค้างชำระ 61 - 90 วัน", "ค้างชำระเกิน 90 วัน")))) -> ชำระตรงเวลา | K12: =IF(OR(F12="",F12="(ว่าง)"), MAX(0,I11-H12), MAX(0,F12-H12)) -> 0 | L12: =IF(K12<=30, "ลูกหนี้ชั้นดี", IF(K12<=90, "ลูกหนี้เฝ้าติดตาม", "ลูกหนี้ด้อยคุณภาพ (NPL)")) -> ลูกหนี้ชั้นดี
A13: d624505038b4dc8617194229beac80401b936aca04d40978acdd1d72a56eb824 | B13: ลำปาง | C13: 7 | D13: 1526010009240 | E13: 46043 | F13: 46048 | G13: 5460 | H13: =E13+C13 -> 46050 | I13: =I12 -> 46253 | J13: =IF(K14<=0, "ชำระตรงเวลา", IF(K14<=30, "ค้างชำระ 1 - 30 วัน", IF(K14<=60, "ค้างชำระ 31 - 60 วัน", IF(K14<=90, "ค้างชำระ 61 - 90 วัน", "ค้างชำระเกิน 90 วัน")))) -> ค้างชำระ 1 - 30 วัน | K13: =IF(OR(F13="",F13="(ว่าง)"), MAX(0,I12-H13), MAX(0,F13-H13)) -> 0 | L13: =IF(K13<=30, "ลูกหนี้ชั้นดี", IF(K13<=90, "ลูกหนี้เฝ้าติดตาม", "ลูกหนี้ด้อยคุณภาพ (NPL)")) -> ลูกหนี้ชั้นดี
A14: 5ef9356aa8a08dc3bfef8b0be13e9ebd2c9560518541939cea0fb1f4a7de9a81 | B14: ลำปาง | C14: 15 | D14: 1526010008519 | E14: 46042 | F14: 46059 | G14: 7080 | H14: =E14+C14 -> 46057 | I14: =I13 -> 46253 | J14: =IF(K15<=0, "ชำระตรงเวลา", IF(K15<=30, "ค้างชำระ 1 - 30 วัน", IF(K15<=60, "ค้างชำระ 31 - 60 วัน", IF(K15<=90, "ค้างชำระ 61 - 90 วัน", "ค้างชำระเกิน 90 วัน")))) -> ชำระตรงเวลา | K14: =IF(OR(F14="",F14="(ว่าง)"), MAX(0,I13-H14), MAX(0,F14-H14)) -> 2 | L14: =IF(K14<=30, "ลูกหนี้ชั้นดี", IF(K14<=90, "ลูกหนี้เฝ้าติดตาม", "ลูกหนี้ด้อยคุณภาพ (NPL)")) -> ลูกหนี้ชั้นดี
... A7810: 130d1ba4a59d47880b97a1c45774ecc2d284342e | B7810: ลำพูน | C7810: 30 | D7810: 1326050014835 | E7810: 46172 | F7810: 46203 | G7810: 6105 | H7810: =E7810+C7810 -> 46202 | I7810: =I7809 -> 46253 | J7810: =IF(K7811<=0, "ชำระตรงเวลา", IF(K7811<=30, "ค้างชำระ 1 - 30 วัน", IF(K7811<=60, "ค้างชำระ 31 - 60 วัน", IF(K7811<=90, "ค้างชำระ 61 - 90 วัน", "ค้างชำระเกิน 90 วัน")))) -> ค้างชำระ 1 - 30 วัน | K7810: =IF(OR(F7810="",F7810="(ว่าง)"), MAX(0,I7809-H7810), MAX(0,F7810-H7810)) -> 1 | L7810: =IF(K7810<=30, "ลูกหนี้ชั้นดี", IF(K7810<=90, "ลูกหนี้เฝ้าติดตาม", "ลูกหนี้ด้อยคุณภาพ (NPL)")) -> ลูกหนี้ชั้นดี
A7811: 130d1ba4a59d47880b97a1c45774ecc2d284342e | B7811: ลำพูน | C7811: 30 | D7811: 1326060014924 | E7811: 46203 | F7811: (ว่าง) | G7811: 6930 | H7811: =E7811+C7811 -> 46233 | I7811: =I7810 -> 46253 | J7811: =IF(K7812<=0, "ชำระตรงเวลา", IF(K7812<=30, "ค้างชำระ 1 - 30 วัน", IF(K7812<=60, "ค้างชำระ 31 - 60 วัน", IF(K7812<=90, "ค้างชำระ 61 - 90 วัน", "ค้างชำระเกิน 90 วัน")))) -> ค้างชำระ 1 - 30 วัน | K7811: =IF(OR(F7811="",F7811="(ว่าง)"), MAX(0,I7810-H7811), MAX(0,F7811-H7811)) -> 20 | L7811: =IF(K7811<=30, "ลูกหนี้ชั้นดี", IF(K7811<=90, "ลูกหนี้เฝ้าติดตาม", "ลูกหนี้ด้อยคุณภาพ (NPL)")) -> ลูกหนี้ชั้นดี
A7812: 5021b76bbfaf48116d0f64caf85f51df08b45cc9 | B7812: พิษณุโลก | C7812: 7 | D7812: 3026010000288 | E7812: 46025 | F7812: 46039 | G7812: 5440 | H7812: =E7812+C7812 -> 46032 | I7812: =I7811 -> 46253 | J7812: =IF(K7813<=0, "ชำระตรงเวลา", IF(K7813<=30, "ค้างชำระ 1 - 30 วัน", IF(K7813<=60, "ค้างชำระ 31 - 60 วัน", IF(K7813<=90, "ค้างชำระ 61 - 90 วัน", "ค้างชำระเกิน 90 วัน")))) -> ค้างชำระ 1 - 30 วัน | K7812: =IF(OR(F7812="",F7812="(ว่าง)"), MAX(0,I7811-H7812), MAX(0,F7812-H7812)) -> 7 | L7812: =IF(K7812<=30, "ลูกหนี้ชั้นดี", IF(K7812<=90, "ลูกหนี้เฝ้าติดตาม", "ลูกหนี้ด้อยคุณภาพ (NPL)")) -> ลูกหนี้ชั้นดี
A7813: 5021b76bbfaf48116d0f64caf85f51df08b45cc9 | B7813: พิษณุโลก | C7813: 7 | D7813: 3026020001718 | E7813: 46055 | F7813: 46064 | G7813: 8755 | H7813: =E7813+C7813 -> 46062 | I7813: =I7812 -> 46253 | J7813: =IF(K7814<=0, "ชำระตรงเวลา", IF(K7814<=30, "ค้างชำระ 1 - 30 วัน", IF(K7814<=60, "ค้างชำระ 31 - 60 วัน", IF(K7814<=90, "ค้างชำระ 61 - 90 วัน", "ค้างชำระเกิน 90 วัน")))) -> ชำระตรงเวลา | K7813: =IF(OR(F7813="",F7813="(ว่าง)"), MAX(0,I7812-H7813), MAX(0,F7813-H7813)) -> 2 | L7813: =IF(K7813<=30, "ลูกหนี้ชั้นดี", IF(K7813<=90, "ลูกหนี้เฝ้าติดตาม", "ลูกหนี้ด้อยคุณภาพ (NPL)")) -> ลูกหนี้ชั้นดี
A7814: 5021b76bbfaf48116d0f64caf85f51df08b45cc9 | B7814: พิษณุโลก | C7814: 7 | D7814: 3026030001630 | E7814: 46083 | F7814: 46088 | G7814: 2107 | H7814: =E7814+C7814 -> 46090 | I7814: =I7813 -> 46253 | J7814: =IF(K7815<=0, "ชำระตรงเวลา", IF(K7815<=30, "ค้างชำระ 1 - 30 วัน", IF(K7815<=60, "ค้างชำระ 31 - 60 วัน", IF(K7815<=90, "ค้างชำระ 61 - 90 วัน", "ค้างชำระเกิน 90 วัน")))) -> ชำระตรงเวลา | K7814: =IF(OR(F7814="",F7814="(ว่าง)"), MAX(0,I7813-H7814), MAX(0,F7814-H7814)) -> 0 | L7814: =IF(K7814<=30, "ลูกหนี้ชั้นดี", IF(K7814<=90, "ลูกหนี้เฝ้าติดตาม", "ลูกหนี้ด้อยคุณภาพ (NPL)")) -> ลูกหนี้ชั้นดี
A7815: 5021b76bbfaf48116d0f64caf85f51df08b45cc9 | B7815: พิษณุโลก | C7815: 7 | D7815: 3026040002085 | E7815: 46114 | F7815: 46121 | G7815: 3548 | H7815: =E7815+C7815 -> 46121 | I7815: =I7814 -> 46253 | J7815: =IF(K7816<=0, "ชำระตรงเวลา", IF(K7816<=30, "ค้างชำระ 1 - 30 วัน", IF(K7816<=60, "ค้างชำระ 31 - 60 วัน", IF(K7816<=90, "ค้างชำระ 61 - 90 วัน", "ค้างชำระเกิน 90 วัน")))) -> ค้างชำระ 1 - 30 วัน | K7815: =IF(OR(F7815="",F7815="(ว่าง)"), MAX(0,I7814-H7815), MAX(0,F7815-H7815)) -> 0 | L7815: =IF(K7815<=30, "ลูกหนี้ชั้นดี", IF(K7815<=90, "ลูกหนี้เฝ้าติดตาม", "ลูกหนี้ด้อยคุณภาพ (NPL)")) -> ลูกหนี้ชั้นดี
A7816: 5021b76bbfaf48116d0f64caf85f51df08b45cc9 | B7816: พิษณุโลก | C7816: 7 | D7816: 3026050001269 | E7816: 46144 | F7816: 46154 | G7816: 2383 | H7816: =E7816+C7816 -> 46151 | I7816: =I7815 -> 46253 | J7816: =IF(K7817<=0, "ชำระตรงเวลา", IF(K7817<=30, "ค้างชำระ 1 - 30 วัน", IF(K7817<=60, "ค้างชำระ 31 - 60 วัน", IF(K7817<=90, "ค้างชำระ 61 - 90 วัน", "ค้างชำระเกิน 90 วัน")))) -> ค้างชำระ 1 - 30 วัน | K7816: =IF(OR(F7816="",F7816="(ว่าง)"), MAX(0,I7815-H7816), MAX(0,F7816-H7816)) -> 3 | L7816: =IF(K7816<=30, "ลูกหนี้ชั้นดี", IF(K7816<=90, "ลูกหนี้เฝ้าติดตาม", "ลูกหนี้ด้อยคุณภาพ (NPL)")) -> ลูกหนี้ชั้นดี
A7817: 5021b76bbfaf48116d0f64caf85f51df08b45cc9 | B7817: พิษณุโลก | C7817: 7 | D7817: 3026060000276 | E7817: 46174 | F7817: 46183 | G7817: 1685 | H7817: =E7817+C7817 -> 46181 | I7817: =I7816 -> 46253 | J7817: =IF(K7818<=0, "ชำระตรงเวลา", IF(K7818<=30, "ค้างชำระ 1 - 30 วัน", IF(K7818<=60, "ค้างชำระ 31 - 60 วัน", IF(K7818<=90, "ค้างชำระ 61 - 90 วัน", "ค้างชำระเกิน 90 วัน")))) -> ชำระตรงเวลา | K7817: =IF(OR(F7817="",F7817="(ว่าง)"), MAX(0,I7816-H7817), MAX(0,F7817-H7817)) -> 2 | L7817: =IF(K7817<=30, "ลูกหนี้ชั้นดี", IF(K7817<=90, "ลูกหนี้เฝ้าติดตาม", "ลูกหนี้ด้อยคุณภาพ (NPL)")) -> ลูกหนี้ชั้นดี
A7818: b3609c479035f9b7ede17c064c412cd936044120 | B7818: เชียงใหม่ | C7818: 7 | D7818: 1126020013529 | E7818: 46083 | F7818: 46088 | G7818: 1680 | H7818: =E7818+C7818 -> 46090 | I7818: =I7817 -> 46253 | J7818: =IF(K7819<=0, "ชำระตรงเวลา", IF(K7819<=30, "ค้างชำระ 1 - 30 วัน", IF(K7819<=60, "ค้างชำระ 31 - 60 วัน", IF(K7819<=90, "ค้างชำระ 61 - 90 วัน", "ค้างชำระเกิน 90 วัน")))) -> ค้างชำระ 1 - 30 วัน | K7818: =IF(OR(F7818="",F7818="(ว่าง)"), MAX(0,I7817-H7818), MAX(0,F7818-H7818)) -> 0 | L7818: =IF(K7818<=30, "ลูกหนี้ชั้นดี", IF(K7818<=90, "ลูกหนี้เฝ้าติดตาม", "ลูกหนี้ด้อยคุณภาพ (NPL)")) -> ลูกหนี้ชั้นดี
A7819: b3609c479035f9b7ede17c064c412cd936044120 | B7819: เชียงใหม่ | C7819: 7 | D7819: 1126030013106 | E7819: 46112 | F7819: 46122 | G7819: 65 | H7819: =E7819+C7819 -> 46119 | I7819: =I7818 -> 46253 | J7819: =IF(K7820<=0, "ชำระตรงเวลา", IF(K7820<=30, "ค้างชำระ 1 - 30 วัน", IF(K7820<=60, "ค้างชำระ 31 - 60 วัน", IF(K7820<=90, "ค้างชำระ 61 - 90 วัน", "ค้างชำระเกิน 90 วัน")))) -> ชำระตรงเวลา | K7819: =IF(OR(F7819="",F7819="(ว่าง)"), MAX(0,I7818-H7819), MAX(0,F7819-H7819)) -> 3 | L7819: =IF(K7819<=30, "ลูกหนี้ชั้นดี", IF(K7819<=90, "ลูกหนี้เฝ้าติดตาม", "ลูกหนี้ด้อยคุณภาพ (NPL)")) -> ลูกหนี้ชั้นดี
A7820: b3609c479035f9b7ede17c064c412cd936044120 | B7820: เชียงใหม่ | C7820: 7 | D7820: 1126030014721 | E7820: 46111 | F7820: 46111 | G7820: 3200 | H7820: =E7820+C7820 -> 46118 | I7820: =I7819 -> 46253 | J7820: =IF(K7821<=0, "ชำระตรงเวลา", IF(K7821<=30, "ค้างชำระ 1 - 30 วัน", IF(K7821<=60, "ค้างชำระ 31 - 60 วัน", IF(K7821<=90, "ค้างชำระ 61 - 90 วัน", "ค้างชำระเกิน 90 วัน")))) -> ชำระตรงเวลา | K7820: =IF(OR(F7820="",F7820="(ว่าง)"), MAX(0,I7819-H7820), MAX(0,F7820-H7820)) -> 0 | L7820: =IF(K7820<=30, "ลูกหนี้ชั้นดี", IF(K7820<=90, "ลูกหนี้เฝ้าติดตาม", "ลูกหนี้ด้อยคุณภาพ (NPL)")) -> ลูกหนี้ชั้นดี
A7821: b3609c479035f9b7ede17c064c412cd936044120 | B7821: เชียงใหม่ | C7821: 7 | D7821: 1126040010669 | E7821: 46140 | F7821: 46147 | G7821: 3349 | H7821: =E7821+C7821 -> 46147 | I7821: =I7820 -> 46253 | J7821: =IF(K7822<=0, "ชำระตรงเวลา", IF(K7822<=30, "ค้างชำระ 1 - 30 วัน", IF(K7822<=60, "ค้างชำระ 31 - 60 วัน", IF(K7822<=90, "ค้างชำระ 61 - 90 วัน", "ค้างชำระเกิน 90 วัน")))) -> ชำระตรงเวลา | K7821: =IF(OR(F7821="",F7821="(ว่าง)"), MAX(0,I7820-H7821), MAX(0,F7821-H7821)) -> 0 | L7821: =IF(K7821<=30, "ลูกหนี้ชั้นดี", IF(K7821<=90, "ลูกหนี้เฝ้าติดตาม", "ลูกหนี้ด้อยคุณภาพ (NPL)")) -> ลูกหนี้ชั้นดี
A7822: b3609c479035f9b7ede17c064c412cd936044120 | B7822: เชียงใหม่ | C7822: 7 | D7822: 1126060003016 | E7822: 46177 | F7822: 46177 | G7822: 222 | H7822: =E7822+C7822 -> 46184 | I7822: =I7821 -> 46253 | J7822: =IF(K7823<=0, "ชำระตรงเวลา", IF(K7823<=30, "ค้างชำระ 1 - 30 วัน", IF(K7823<=60, "ค้างชำระ 31 - 60 วัน", IF(K7823<=90, "ค้างชำระ 61 - 90 วัน", "ค้างชำระเกิน 90 วัน")))) -> ชำระตรงเวลา | K7822: =IF(OR(F7822="",F7822="(ว่าง)"), MAX(0,I7821-H7822), MAX(0,F7822-H7822)) -> 0 | L7822: =IF(K7822<=30, "ลูกหนี้ชั้นดี", IF(K7822<=90, "ลูกหนี้เฝ้าติดตาม", "ลูกหนี้ด้อยคุณภาพ (NPL)")) -> ลูกหนี้ชั้นดี
A7823: b3609c479035f9b7ede17c064c412cd936044120 | B7823: เชียงใหม่ | C7823: 7 | D7823: 1126060003658 | E7823: 46182 | F7823: 46189 | G7823: 3004 | H7823: =E7823+C7823 -> 46189 | I7823: =I7822 -> 46253 | J7823: =IF(K7824<=0, "ชำระตรงเวลา", IF(K7824<=30, "ค้างชำระ 1 - 30 วัน", IF(K7824<=60, "ค้างชำระ 31 - 60 วัน", IF(K7824<=90, "ค้างชำระ 61 - 90 วัน", "ค้างชำระเกิน 90 วัน")))) -> ชำระตรงเวลา | K7823: =IF(OR(F7823="",F7823="(ว่าง)"), MAX(0,I7822-H7823), MAX(0,F7823-H7823)) -> 0 | L7823: =IF(K7823<=30, "ลูกหนี้ชั้นดี", IF(K7823<=90, "ลูกหนี้เฝ้าติดตาม", "ลูกหนี้ด้อยคุณภาพ (NPL)")) -> ลูกหนี้ชั้นดี
... A7956: 959d5742df955ab837934a4d4aa476cb9bfe7e3f | B7956: เชียงใหม่ | C7956: 30 | D7956: 1126040007010 | E7956: 46133 | F7956: 46181 | G7956: 10356 | H7956: =E7956+C7956 -> 46163 | I7956: =I7955 -> 46253 | J7956: =IF(K7957<=0, "ชำระตรงเวลา", IF(K7957<=30, "ค้างชำระ 1 - 30 วัน", IF(K7957<=60, "ค้างชำระ 31 - 60 วัน", IF(K7957<=90, "ค้างชำระ 61 - 90 วัน", "ค้างชำระเกิน 90 วัน")))) -> ค้างชำระ 31 - 60 วัน | K7956: =IF(OR(F7956="",F7956="(ว่าง)"), MAX(0,I7955-H7956), MAX(0,F7956-H7956)) -> 18 | L7956: =IF(K7956<=30, "ลูกหนี้ชั้นดี", IF(K7956<=90, "ลูกหนี้เฝ้าติดตาม", "ลูกหนี้ด้อยคุณภาพ (NPL)")) -> ลูกหนี้ชั้นดี
A7957: 959d5742df955ab837934a4d4aa476cb9bfe7e3f | B7957: เชียงใหม่ | C7957: 30 | D7957: 1126060002668 | E7957: 46182 | F7957: (ว่าง) | G7957: 2816 | H7957: =E7957+C7957 -> 46212 | I7957: =I7956 -> 46253 | J7957: =IF(K7958<=0, "ชำระตรงเวลา", IF(K7958<=30, "ค้างชำระ 1 - 30 วัน", IF(K7958<=60, "ค้างชำระ 31 - 60 วัน", IF(K7958<=90, "ค้างชำระ 61 - 90 วัน", "ค้างชำระเกิน 90 วัน")))) -> ค้างชำระ 31 - 60 วัน | K7957: =IF(OR(F7957="",F7957="(ว่าง)"), MAX(0,I7956-H7957), MAX(0,F7957-H7957)) -> 41 | L7957: =IF(K7957<=30, "ลูกหนี้ชั้นดี", IF(K7957<=90, "ลูกหนี้เฝ้าติดตาม", "ลูกหนี้ด้อยคุณภาพ (NPL)")) -> ลูกหนี้เฝ้าติดตาม
A7958: 959d5742df955ab837934a4d4aa476cb9bfe7e3f | B7958: เชียงใหม่ | C7958: 30 | D7958: 1126060006253 | E7958: 46185 | F7958: (ว่าง) | G7958: 10849 | H7958: =E7958+C7958 -> 46215 | I7958: =I7957 -> 46253 | J7958: =IF(K7959<=0, "ชำระตรงเวลา", IF(K7959<=30, "ค้างชำระ 1 - 30 วัน", IF(K7959<=60, "ค้างชำระ 31 - 60 วัน", IF(K7959<=90, "ค้างชำระ 61 - 90 วัน", "ค้างชำระเกิน 90 วัน")))) -> ค้างชำระ 31 - 60 วัน | K7958: =IF(OR(F7958="",F7958="(ว่าง)"), MAX(0,I7957-H7958), MAX(0,F7958-H7958)) -> 38 | L7958: =IF(K7958<=30, "ลูกหนี้ชั้นดี", IF(K7958<=90, "ลูกหนี้เฝ้าติดตาม", "ลูกหนี้ด้อยคุณภาพ (NPL)")) -> ลูกหนี้เฝ้าติดตาม
A7959: 959d5742df955ab837934a4d4aa476cb9bfe7e3f | B7959: เชียงใหม่ | C7959: 30 | D7959: 1126060010038 | E7959: 46191 | F7959: (ว่าง) | G7959: 2928 | H7959: =E7959+C7959 -> 46221 | I7959: =I7958 -> 46253 | J7959: =IF(K7960<=0, "ชำระตรงเวลา", IF(K7960<=30, "ค้างชำระ 1 - 30 วัน", IF(K7960<=60, "ค้างชำระ 31 - 60 วัน", IF(K7960<=90, "ค้างชำระ 61 - 90 วัน", "ค้างชำระเกิน 90 วัน")))) -> ค้างชำระ 1 - 30 วัน | K7959: =IF(OR(F7959="",F7959="(ว่าง)"), MAX(0,I7958-H7959), MAX(0,F7959-H7959)) -> 32 | L7959: =IF(K7959<=30, "ลูกหนี้ชั้นดี", IF(K7959<=90, "ลูกหนี้เฝ้าติดตาม", "ลูกหนี้ด้อยคุณภาพ (NPL)")) -> ลูกหนี้เฝ้าติดตาม
A7960: 959d5742df955ab837934a4d4aa476cb9bfe7e3f | B7960: เชียงใหม่ | C7960: 30 | D7960: 1126060013114 | E7960: 46200 | F7960: (ว่าง) | G7960: 14856 | H7960: =E7960+C7960 -> 46230 | I7960: =I7959 -> 46253 | J7960: =IF(K7961<=0, "ชำระตรงเวลา", IF(K7961<=30, "ค้างชำระ 1 - 30 วัน", IF(K7961<=60, "ค้างชำระ 31 - 60 วัน", IF(K7961<=90, "ค้างชำระ 61 - 90 วัน", "ค้างชำระเกิน 90 วัน")))) -> ค้างชำระ 1 - 30 วัน | K7960: =IF(OR(F7960="",F7960="(ว่าง)"), MAX(0,I7959-H7960), MAX(0,F7960-H7960)) -> 23 | L7960: =IF(K7960<=30, "ลูกหนี้ชั้นดี", IF(K7960<=90, "ลูกหนี้เฝ้าติดตาม", "ลูกหนี้ด้อยคุณภาพ (NPL)")) -> ลูกหนี้ชั้นดี
A7961: 2954cbb6383eba5ed88c06b0ce98f8e0090be3ef | B7961: เชียงใหม่ | C7961: 7 | D7961: 1126020013901 | E7961: 46083 | F7961: 46091 | G7961: 430 | H7961: =E7961+C7961 -> 46090 | I7961: =I7960 -> 46253 | J7961: =IF(K7962<=0, "ชำระตรงเวลา", IF(K7962<=30, "ค้างชำระ 1 - 30 วัน", IF(K7962<=60, "ค้างชำระ 31 - 60 วัน", IF(K7962<=90, "ค้างชำระ 61 - 90 วัน", "ค้างชำระเกิน 90 วัน")))) -> ค้างชำระ 1 - 30 วัน | K7961: =IF(OR(F7961="",F7961="(ว่าง)"), MAX(0,I7960-H7961), MAX(0,F7961-H7961)) -> 1 | L7961: =IF(K7961<=30, "ลูกหนี้ชั้นดี", IF(K7961<=90, "ลูกหนี้เฝ้าติดตาม", "ลูกหนี้ด้อยคุณภาพ (NPL)")) -> ลูกหนี้ชั้นดี
A7962: 2954cbb6383eba5ed88c06b0ce98f8e0090be3ef | B7962: เชียงใหม่ | C7962: 7 | D7962: 1126030010662 | E7962: 46104 | F7962: 46114 | G7962: 1010 | H7962: =E7962+C7962 -> 46111 | I7962: =I7961 -> 46253 | J7962: =IF(K7963<=0, "ชำระตรงเวลา", IF(K7963<=30, "ค้างชำระ 1 - 30 วัน", IF(K7963<=60, "ค้างชำระ 31 - 60 วัน", IF(K7963<=90, "ค้างชำระ 61 - 90 วัน", "ค้างชำระเกิน 90 วัน")))) -> ค้างชำระ 1 - 30 วัน | K7962: =IF(OR(F7962="",F7962="(ว่าง)"), MAX(0,I7961-H7962), MAX(0,F7962-H7962)) -> 3 | L7962: =IF(K7962<=30, "ลูกหนี้ชั้นดี", IF(K7962<=90, "ลูกหนี้เฝ้าติดตาม", "ลูกหนี้ด้อยคุณภาพ (NPL)")) -> ลูกหนี้ชั้นดี
A7963: 2954cbb6383eba5ed88c06b0ce98f8e0090be3ef | B7963: เชียงใหม่ | C7963: 7 | D7963: 1126050006867 | E7963: 46160 | F7963: 46170 | G7963: 404 | H7963: =E7963+C7963 -> 46167 | I7963: =I7962 -> 46253 | J7963: =IF(K7964<=0, "ชำระตรงเวลา", IF(K7964<=30, "ค้างชำระ 1 - 30 วัน", IF(K7964<=60, "ค้างชำระ 31 - 60 วัน", IF(K7964<=90, "ค้างชำระ 61 - 90 วัน", "ค้างชำระเกิน 90 วัน")))) -> ชำระตรงเวลา | K7963: =IF(OR(F7963="",F7963="(ว่าง)"), MAX(0,I7962-H7963), MAX(0,F7963-H7963)) -> 3 | L7963: =IF(K7963<=30, "ลูกหนี้ชั้นดี", IF(K7963<=90, "ลูกหนี้เฝ้าติดตาม", "ลูกหนี้ด้อยคุณภาพ (NPL)")) -> ลูกหนี้ชั้นดี
A7964: 2954cbb6383eba5ed88c06b0ce98f8e0090be3ef | B7964: เชียงใหม่ | C7964: 7 | D7964: 1126060001920 | E7964: 46182 | F7964: 46185 | G7964: 862 | H7964: =E7964+C7964 -> 46189 | I7964: =I7963 -> 46253 | J7964: =IF(K7965<=0, "ชำระตรงเวลา", IF(K7965<=30, "ค้างชำระ 1 - 30 วัน", IF(K7965<=60, "ค้างชำระ 31 - 60 วัน", IF(K7965<=90, "ค้างชำระ 61 - 90 วัน", "ค้างชำระเกิน 90 วัน")))) -> ชำระตรงเวลา | K7964: =IF(OR(F7964="",F7964="(ว่าง)"), MAX(0,I7963-H7964), MAX(0,F7964-H7964)) -> 0 | L7964: =IF(K7964<=30, "ลูกหนี้ชั้นดี", IF(K7964<=90, "ลูกหนี้เฝ้าติดตาม", "ลูกหนี้ด้อยคุณภาพ (NPL)")) -> ลูกหนี้ชั้นดี
A7965: 2954cbb6383eba5ed88c06b0ce98f8e0090be3ef | B7965: เชียงใหม่ | C7965: 7 | D7965: 1126060006482 | E7965: 46188 | F7965: 46191 | G7965: 583 | H7965: =E7965+C7965 -> 46195 | I7965: =I7964 -> 46253 | J7965: =IF(K7966<=0, "ชำระตรงเวลา", IF(K7966<=30, "ค้างชำระ 1 - 30 วัน", IF(K7966<=60, "ค้างชำระ 31 - 60 วัน", IF(K7966<=90, "ค้างชำระ 61 - 90 วัน", "ค้างชำระเกิน 90 วัน")))) -> ชำระตรงเวลา | K7965: =IF(OR(F7965="",F7965="(ว่าง)"), MAX(0,I7964-H7965), MAX(0,F7965-H7965)) -> 0 | L7965: =IF(K7965<=30, "ลูกหนี้ชั้นดี", IF(K7965<=90, "ลูกหนี้เฝ้าติดตาม", "ลูกหนี้ด้อยคุณภาพ (NPL)")) -> ลูกหนี้ชั้นดี
A7966: 2954cbb6383eba5ed88c06b0ce98f8e0090be3ef | B7966: เชียงใหม่ | C7966: 7 | D7966: 1126060010397 | E7966: 46195 | F7966: 46198 | G7966: 496 | H7966: =E7966+C7966 -> 46202 | I7966: =I7965 -> 46253 | J7966: =IF(K7967<=0, "ชำระตรงเวลา", IF(K7967<=30, "ค้างชำระ 1 - 30 วัน", IF(K7967<=60, "ค้างชำระ 31 - 60 วัน", IF(K7967<=90, "ค้างชำระ 61 - 90 วัน", "ค้างชำระเกิน 90 วัน")))) -> ค้างชำระ 1 - 30 วัน | K7966: =IF(OR(F7966="",F7966="(ว่าง)"), MAX(0,I7965-H7966), MAX(0,F7966-H7966)) -> 0 | L7966: =IF(K7966<=30, "ลูกหนี้ชั้นดี", IF(K7966<=90, "ลูกหนี้เฝ้าติดตาม", "ลูกหนี้ด้อยคุณภาพ (NPL)")) -> ลูกหนี้ชั้นดี
A7967: 2954cbb6383eba5ed88c06b0ce98f8e0090be3ef | B7967: เชียงใหม่ | C7967: 7 | D7967: 1126060013411 | E7967: 46202 | F7967: 46213 | G7967: 547 | H7967: =E7967+C7967 -> 46209 | I7967: =I7966 -> 46253 | J7967: =IF(K7968<=0, "ชำระตรงเวลา", IF(K7968<=30, "ค้างชำระ 1 - 30 วัน", IF(K7968<=60, "ค้างชำระ 31 - 60 วัน", IF(K7968<=90, "ค้างชำระ 61 - 90 วัน", "ค้างชำระเกิน 90 วัน")))) -> ชำระตรงเวลา | K7967: =IF(OR(F7967="",F7967="(ว่าง)"), MAX(0,I7966-H7967), MAX(0,F7967-H7967)) -> 4 | L7967: =IF(K7967<=30, "ลูกหนี้ชั้นดี", IF(K7967<=90, "ลูกหนี้เฝ้าติดตาม", "ลูกหนี้ด้อยคุณภาพ (NPL)")) -> ลูกหนี้ชั้นดี
...

Sheet สรุปลูกหนี้
A1: ชื่อลูกหนี้ | B1: จำนวนบิลทั้งหมด | C1: จำนวนบิลที่ช้า | D1: รวมวันช้า | E1: วันช้าสูงสุด | F1: เปอร์เซนต์บิลที่ช้า | G1: กลุ่มช่วงอายุลูกหนี้ | H1: การแบ่งชั้นลูกหนี้ (TFRS 9) | I1: ความเสี่ยง | J1: ยอดไม่ค้าง (0 วัน) | K1: ยอดค้าง 1-30 วัน | L1: ยอดค้าง 31-60 วัน | M1: ยอดค้าง 61-90 วัน | N1: ยอดค้างเกิน 90 วัน | O1: รวมยอดทั้งหมด | P1: ความเสี่ยงถ่วงน้ำหนัก
A2: {=_xlfn.UNIQUE(Table2[ชื่อลูกหนี้])} -> 1ffd1b76f559a74aa8c6ebe473d24404afad7a1bb7ac8f9e019b6ec17993fe6d | B2: =COUNTIF(รายงานลูกหนี้!$A:$A,A2) -> 2 | C2: =COUNTIFS(รายงานลูกหนี้!$A:$A,A2,รายงานลูกหนี้!$K:$K,">0") -> 1 | D2: =SUMIF(รายงานลูกหนี้!$A:$A,A2,รายงานลูกหนี้!$K:$K) -> 4 | E2: =_xlfn.MAXIFS(รายงานลูกหนี้!$K:$K,รายงานลูกหนี้!$A:$A,A2) -> 4 | F2: =C2/B2 -> 0.5 | G2: =IF(E2<=0, "ชำระตรงเวลา", IF(E2<=30, "ค้างชำระ 1 - 30 วัน", IF(E2<=60, "ค้างชำระ 31 - 60 วัน", IF(E2<=90, "ค้างชำระ 61 - 90 วัน", "ค้างชำระเกิน 90 วัน")))) -> ค้างชำระ 1 - 30 วัน | H2: =IF(E2<=30, "ลูกหนี้ชั้นดี", IF(E2<=90, "ลูกหนี้เฝ้าติดตาม", "ลูกหนี้ด้อยคุณภาพ (NPL)")) -> ลูกหนี้ชั้นดี | I2: {=_xlfn.IFS(D2=0,0%, D2<=30,25%, D2<=60,50%, D2<=90,75%, D2>90,100%)} -> 0.25 | J2: =SUMIFS(รายงานลูกหนี้!$G$2:$G$20000, รายงานลูกหนี้!$A$2:$A$20000, $A2, รายงานลูกหนี้!$K$2:$K$20000, 0) -> 2920 | K2: =SUMIFS(รายงานลูกหนี้!$G$2:$G$20000, รายงานลูกหนี้!$A$2:$A$20000, $A2, รายงานลูกหนี้!$K$2:$K$20000, ">=1", รายงานลูกหนี้!$K$2:$K$20000, "<=30") -> 900 | L2: =SUMIFS(รายงานลูกหนี้!$G$2:$G$20000, รายงานลูกหนี้!$A$2:$A$20000, $A2, รายงานลูกหนี้!$K$2:$K$20000, ">=31", รายงานลูกหนี้!$K$2:$K$20000, "<=60") -> 0 | M2: =SUMIFS(รายงานลูกหนี้!$G$2:$G$20000, รายงานลูกหนี้!$A$2:$A$20000, $A2, รายงานลูกหนี้!$K$2:$K$20000, ">=61", รายงานลูกหนี้!$K$2:$K$20000, "<=90") -> 0 | N2: =SUMIFS(รายงานลูกหนี้!$G$2:$G$20000, รายงานลูกหนี้!$A$2:$A$20000, $A2, รายงานลูกหนี้!$K$2:$K$20000, ">90") -> 0 | O2: =SUM(J2:N2) -> 3820 | P2: =IF(O2=0, 0%, (J2*0%+K2*25%+L2*50%+M2*75%+N2*100%)/O2) -> 0.058900524
A3: bffb4c8260b96f7a32415a51753355e53d31f418fb1ed184109d6d681a358817 | B3: =COUNTIF(รายงานลูกหนี้!$A:$A,A3) -> 1 | C3: =COUNTIFS(รายงานลูกหนี้!$A:$A,A3,รายงานลูกหนี้!$K:$K,">0") -> 0 | D3: =SUMIF(รายงานลูกหนี้!$A:$A,A3,รายงานลูกหนี้!$K:$K) -> 0 | E3: =_xlfn.MAXIFS(รายงานลูกหนี้!$K:$K,รายงานลูกหนี้!$A:$A,A3) -> 0 | F3: =C3/B3 -> 0 | G3: =IF(E3<=0, "ชำระตรงเวลา", IF(E3<=30, "ค้างชำระ 1 - 30 วัน", IF(E3<=60, "ค้างชำระ 31 - 60 วัน", IF(E3<=90, "ค้างชำระ 61 - 90 วัน", "ค้างชำระเกิน 90 วัน")))) -> ชำระตรงเวลา | H3: =IF(E3<=30, "ลูกหนี้ชั้นดี", IF(E3<=90, "ลูกหนี้เฝ้าติดตาม", "ลูกหนี้ด้อยคุณภาพ (NPL)")) -> ลูกหนี้ชั้นดี | I3: {=_xlfn.IFS(D3=0,0%, D3<=30,25%, D3<=60,50%, D3<=90,75%, D3>90,100%)} -> 0 | J3: =SUMIFS(รายงานลูกหนี้!$G$2:$G$20000, รายงานลูกหนี้!$A$2:$A$20000, $A3, รายงานลูกหนี้!$K$2:$K$20000, 0) -> 60 | K3: =SUMIFS(รายงานลูกหนี้!$G$2:$G$20000, รายงานลูกหนี้!$A$2:$A$20000, $A3, รายงานลูกหนี้!$K$2:$K$20000, ">=1", รายงานลูกหนี้!$K$2:$K$20000, "<=30") -> 0 | L3: =SUMIFS(รายงานลูกหนี้!$G$2:$G$20000, รายงานลูกหนี้!$A$2:$A$20000, $A3, รายงานลูกหนี้!$K$2:$K$20000, ">=31", รายงานลูกหนี้!$K$2:$K$20000, "<=60") -> 0 | M3: =SUMIFS(รายงานลูกหนี้!$G$2:$G$20000, รายงานลูกหนี้!$A$2:$A$20000, $A3, รายงานลูกหนี้!$K$2:$K$20000, ">=61", รายงานลูกหนี้!$K$2:$K$20000, "<=90") -> 0 | N3: =SUMIFS(รายงานลูกหนี้!$G$2:$G$20000, รายงานลูกหนี้!$A$2:$A$20000, $A3, รายงานลูกหนี้!$K$2:$K$20000, ">90") -> 0 | O3: =SUM(J3:N3) -> 60 | P3: =IF(O3=0, 0%, (J3*0%+K3*25%+L3*50%+M3*75%+N3*100%)/O3) -> 0
A4: f57f896561c9744b813a45d7559080a4a65523a63f3434d8b51daff767d9231f | B4: =COUNTIF(รายงานลูกหนี้!$A:$A,A4) -> 1 | C4: =COUNTIFS(รายงานลูกหนี้!$A:$A,A4,รายงานลูกหนี้!$K:$K,">0") -> 1 | D4: =SUMIF(รายงานลูกหนี้!$A:$A,A4,รายงานลูกหนี้!$K:$K) -> 1 | E4: =_xlfn.MAXIFS(รายงานลูกหนี้!$K:$K,รายงานลูกหนี้!$A:$A,A4) -> 1 | F4: =C4/B4 -> 1 | G4: =IF(E4<=0, "ชำระตรงเวลา", IF(E4<=30, "ค้างชำระ 1 - 30 วัน", IF(E4<=60, "ค้างชำระ 31 - 60 วัน", IF(E4<=90, "ค้างชำระ 61 - 90 วัน", "ค้างชำระเกิน 90 วัน")))) -> ค้างชำระ 1 - 30 วัน | H4: =IF(E4<=30, "ลูกหนี้ชั้นดี", IF(E4<=90, "ลูกหนี้เฝ้าติดตาม", "ลูกหนี้ด้อยคุณภาพ (NPL)")) -> ลูกหนี้ชั้นดี | I4: {=_xlfn.IFS(D4=0,0%, D4<=30,25%, D4<=60,50%, D4<=90,75%, D4>90,100%)} -> 0.25 | J4: =SUMIFS(รายงานลูกหนี้!$G$2:$G$20000, รายงานลูกหนี้!$A$2:$A$20000, $A4, รายงานลูกหนี้!$K$2:$K$20000, 0) -> 0 | K4: =SUMIFS(รายงานลูกหนี้!$G$2:$G$20000, รายงานลูกหนี้!$A$2:$A$20000, $A4, รายงานลูกหนี้!$K$2:$K$20000, ">=1", รายงานลูกหนี้!$K$2:$K$20000, "<=30") -> 825 | L4: =SUMIFS(รายงานลูกหนี้!$G$2:$G$20000, รายงานลูกหนี้!$A$2:$A$20000, $A4, รายงานลูกหนี้!$K$2:$K$20000, ">=31", รายงานลูกหนี้!$K$2:$K$20000, "<=60") -> 0 | M4: =SUMIFS(รายงานลูกหนี้!$G$2:$G$20000, รายงานลูกหนี้!$A$2:$A$20000, $A4, รายงานลูกหนี้!$K$2:$K$20000, ">=61", รายงานลูกหนี้!$K$2:$K$20000, "<=90") -> 0 | N4: =SUMIFS(รายงานลูกหนี้!$G$2:$G$20000, รายงานลูกหนี้!$A$2:$A$20000, $A4, รายงานลูกหนี้!$K$2:$K$20000, ">90") -> 0 | O4: =SUM(J4:N4) -> 825 | P4: =IF(O4=0, 0%, (J4*0%+K4*25%+L4*50%+M4*75%+N4*100%)/O4) -> 0.25
A5: 738e4c9a89f462bcca485657195e9a598fd42a9babb103493de6081512c10c19 | B5: =COUNTIF(รายงานลูกหนี้!$A:$A,A5) -> 2 | C5: =COUNTIFS(รายงานลูกหนี้!$A:$A,A5,รายงานลูกหนี้!$K:$K,">0") -> 0 | D5: =SUMIF(รายงานลูกหนี้!$A:$A,A5,รายงานลูกหนี้!$K:$K) -> 0 | E5: =_xlfn.MAXIFS(รายงานลูกหนี้!$K:$K,รายงานลูกหนี้!$A:$A,A5) -> 0 | F5: =C5/B5 -> 0 | G5: =IF(E5<=0, "ชำระตรงเวลา", IF(E5<=30, "ค้างชำระ 1 - 30 วัน", IF(E5<=60, "ค้างชำระ 31 - 60 วัน", IF(E5<=90, "ค้างชำระ 61 - 90 วัน", "ค้างชำระเกิน 90 วัน")))) -> ชำระตรงเวลา | H5: =IF(E5<=30, "ลูกหนี้ชั้นดี", IF(E5<=90, "ลูกหนี้เฝ้าติดตาม", "ลูกหนี้ด้อยคุณภาพ (NPL)")) -> ลูกหนี้ชั้นดี | I5: {=_xlfn.IFS(D5=0,0%, D5<=30,25%, D5<=60,50%, D5<=90,75%, D5>90,100%)} -> 0 | J5: =SUMIFS(รายงานลูกหนี้!$G$2:$G$20000, รายงานลูกหนี้!$A$2:$A$20000, $A5, รายงานลูกหนี้!$K$2:$K$20000, 0) -> 14420 | K5: =SUMIFS(รายงานลูกหนี้!$G$2:$G$20000, รายงานลูกหนี้!$A$2:$A$20000, $A5, รายงานลูกหนี้!$K$2:$K$20000, ">=1", รายงานลูกหนี้!$K$2:$K$20000, "<=30") -> 0 | L5: =SUMIFS(รายงานลูกหนี้!$G$2:$G$20000, รายงานลูกหนี้!$A$2:$A$20000, $A5, รายงานลูกหนี้!$K$2:$K$20000, ">=31", รายงานลูกหนี้!$K$2:$K$20000, "<=60") -> 0 | M5: =SUMIFS(รายงานลูกหนี้!$G$2:$G$20000, รายงานลูกหนี้!$A$2:$A$20000, $A5, รายงานลูกหนี้!$K$2:$K$20000, ">=61", รายงานลูกหนี้!$K$2:$K$20000, "<=90") -> 0 | N5: =SUMIFS(รายงานลูกหนี้!$G$2:$G$20000, รายงานลูกหนี้!$A$2:$A$20000, $A5, รายงานลูกหนี้!$K$2:$K$20000, ">90") -> 0 | O5: =SUM(J5:N5) -> 14420 | P5: =IF(O5=0, 0%, (J5*0%+K5*25%+L5*50%+M5*75%+N5*100%)/O5) -> 0
A6: 50ed86b5f35eb2271f958e9d1f331d0a9eeae7b50a10f8e3bd67368264b1e489 | B6: =COUNTIF(รายงานลูกหนี้!$A:$A,A6) -> 1 | C6: =COUNTIFS(รายงานลูกหนี้!$A:$A,A6,รายงานลูกหนี้!$K:$K,">0") -> 0 | D6: =SUMIF(รายงานลูกหนี้!$A:$A,A6,รายงานลูกหนี้!$K:$K) -> 0 | E6: =_xlfn.MAXIFS(รายงานลูกหนี้!$K:$K,รายงานลูกหนี้!$A:$A,A6) -> 0 | F6: =C6/B6 -> 0 | G6: =IF(E6<=0, "ชำระตรงเวลา", IF(E6<=30, "ค้างชำระ 1 - 30 วัน", IF(E6<=60, "ค้างชำระ 31 - 60 วัน", IF(E6<=90, "ค้างชำระ 61 - 90 วัน", "ค้างชำระเกิน 90 วัน")))) -> ชำระตรงเวลา | H6: =IF(E6<=30, "ลูกหนี้ชั้นดี", IF(E6<=90, "ลูกหนี้เฝ้าติดตาม", "ลูกหนี้ด้อยคุณภาพ (NPL)")) -> ลูกหนี้ชั้นดี | I6: {=_xlfn.IFS(D6=0,0%, D6<=30,25%, D6<=60,50%, D6<=90,75%, D6>90,100%)} -> 0 | J6: =SUMIFS(รายงานลูกหนี้!$G$2:$G$20000, รายงานลูกหนี้!$A$2:$A$20000, $A6, รายงานลูกหนี้!$K$2:$K$20000, 0) -> 2075 | K6: =SUMIFS(รายงานลูกหนี้!$G$2:$G$20000, รายงานลูกหนี้!$A$2:$A$20000, $A6, รายงานลูกหนี้!$K$2:$K$20000, ">=1", รายงานลูกหนี้!$K$2:$K$20000, "<=30") -> 0 | L6: =SUMIFS(รายงานลูกหนี้!$G$2:$G$20000, รายงานลูกหนี้!$A$2:$A$20000, $A6, รายงานลูกหนี้!$K$2:$K$20000, ">=31", รายงานลูกหนี้!$K$2:$K$20000, "<=60") -> 0 | M6: =SUMIFS(รายงานลูกหนี้!$G$2:$G$20000, รายงานลูกหนี้!$A$2:$A$20000, $A6, รายงานลูกหนี้!$K$2:$K$20000, ">=61", รายงานลูกหนี้!$K$2:$K$20000, "<=90") -> 0 | N6: =SUMIFS(รายงานลูกหนี้!$G$2:$G$20000, รายงานลูกหนี้!$A$2:$A$20000, $A6, รายงานลูกหนี้!$K$2:$K$20000, ">90") -> 0 | O6: =SUM(J6:N6) -> 2075 | P6: =IF(O6=0, 0%, (J6*0%+K6*25%+L6*50%+M6*75%+N6*100%)/O6) -> 0
A7: c07e4e324959006e76c15356ba0403db32c9bb122aef4882ebeaecc4eb47dde3 | B7: =COUNTIF(รายงานลูกหนี้!$A:$A,A7) -> 2 | C7: =COUNTIFS(รายงานลูกหนี้!$A:$A,A7,รายงานลูกหนี้!$K:$K,">0") -> 2 | D7: =SUMIF(รายงานลูกหนี้!$A:$A,A7,รายงานลูกหนี้!$K:$K) -> 7 | E7: =_xlfn.MAXIFS(รายงานลูกหนี้!$K:$K,รายงานลูกหนี้!$A:$A,A7) -> 5 | F7: =C7/B7 -> 1 | G7: =IF(E7<=0, "ชำระตรงเวลา", IF(E7<=30, "ค้างชำระ 1 - 30 วัน", IF(E7<=60, "ค้างชำระ 31 - 60 วัน", IF(E7<=90, "ค้างชำระ 61 - 90 วัน", "ค้างชำระเกิน 90 วัน")))) -> ค้างชำระ 1 - 30 วัน | H7: =IF(E7<=30, "ลูกหนี้ชั้นดี", IF(E7<=90, "ลูกหนี้เฝ้าติดตาม", "ลูกหนี้ด้อยคุณภาพ (NPL)")) -> ลูกหนี้ชั้นดี | I7: {=_xlfn.IFS(D7=0,0%, D7<=30,25%, D7<=60,50%, D7<=90,75%, D7>90,100%)} -> 0.25 | J7: =SUMIFS(รายงานลูกหนี้!$G$2:$G$20000, รายงานลูกหนี้!$A$2:$A$20000, $A7, รายงานลูกหนี้!$K$2:$K$20000, 0) -> 0 | K7: =SUMIFS(รายงานลูกหนี้!$G$2:$G$20000, รายงานลูกหนี้!$A$2:$A$20000, $A7, รายงานลูกหนี้!$K$2:$K$20000, ">=1", รายงานลูกหนี้!$K$2:$K$20000, "<=30") -> 10864 | L7: =SUMIFS(รายงานลูกหนี้!$G$2:$G$20000, รายงานลูกหนี้!$A$2:$A$20000, $A7, รายงานลูกหนี้!$K$2:$K$20000, ">=31", รายงานลูกหนี้!$K$2:$K$20000, "<=60") -> 0 | M7: =SUMIFS(รายงานลูกหนี้!$G$2:$G$20000, รายงานลูกหนี้!$A$2:$A$20000, $A7, รายงานลูกหนี้!$K$2:$K$20000, ">=61", รายงานลูกหนี้!$K$2:$K$20000, "<=90") -> 0 | N7: =SUMIFS(รายงานลูกหนี้!$G$2:$G$20000, รายงานลูกหนี้!$A$2:$A$20000, $A7, รายงานลูกหนี้!$K$2:$K$20000, ">90") -> 0 | O7: =SUM(J7:N7) -> 10864 | P7: =IF(O7=0, 0%, (J7*0%+K7*25%+L7*50%+M7*75%+N7*100%)/O7) -> 0.25
A8: 07a3531a5a5dcc04dffc460ce464d6d9f55098d0e6a50ff21be397c2c4ecaa57 | B8: =COUNTIF(รายงานลูกหนี้!$A:$A,A8) -> 1 | C8: =COUNTIFS(รายงานลูกหนี้!$A:$A,A8,รายงานลูกหนี้!$K:$K,">0") -> 0 | D8: =SUMIF(รายงานลูกหนี้!$A:$A,A8,รายงานลูกหนี้!$K:$K) -> 0 | E8: =_xlfn.MAXIFS(รายงานลูกหนี้!$K:$K,รายงานลูกหนี้!$A:$A,A8) -> 0 | F8: =C8/B8 -> 0 | G8: =IF(E8<=0, "ชำระตรงเวลา", IF(E8<=30, "ค้างชำระ 1 - 30 วัน", IF(E8<=60, "ค้างชำระ 31 - 60 วัน", IF(E8<=90, "ค้างชำระ 61 - 90 วัน", "ค้างชำระเกิน 90 วัน")))) -> ชำระตรงเวลา | H8: =IF(E8<=30, "ลูกหนี้ชั้นดี", IF(E8<=90, "ลูกหนี้เฝ้าติดตาม", "ลูกหนี้ด้อยคุณภาพ (NPL)")) -> ลูกหนี้ชั้นดี | I8: {=_xlfn.IFS(D8=0,0%, D8<=30,25%, D8<=60,50%, D8<=90,75%, D8>90,100%)} -> 0 | J8: =SUMIFS(รายงานลูกหนี้!$G$2:$G$20000, รายงานลูกหนี้!$A$2:$A$20000, $A8, รายงานลูกหนี้!$K$2:$K$20000, 0) -> 390 | K8: =SUMIFS(รายงานลูกหนี้!$G$2:$G$20000, รายงานลูกหนี้!$A$2:$A$20000, $A8, รายงานลูกหนี้!$K$2:$K$20000, ">=1", รายงานลูกหนี้!$K$2:$K$20000, "<=30") -> 0 | L8: =SUMIFS(รายงานลูกหนี้!$G$2:$G$20000, รายงานลูกหนี้!$A$2:$A$20000, $A8, รายงานลูกหนี้!$K$2:$K$20000, ">=31", รายงานลูกหนี้!$K$2:$K$20000, "<=60") -> 0 | M8: =SUMIFS(รายงานลูกหนี้!$G$2:$G$20000, รายงานลูกหนี้!$A$2:$A$20000, $A8, รายงานลูกหนี้!$K$2:$K$20000, ">=61", รายงานลูกหนี้!$K$2:$K$20000, "<=90") -> 0 | N8: =SUMIFS(รายงานลูกหนี้!$G$2:$G$20000, รายงานลูกหนี้!$A$2:$A$20000, $A8, รายงานลูกหนี้!$K$2:$K$20000, ">90") -> 0 | O8: =SUM(J8:N8) -> 390 | P8: =IF(O8=0, 0%, (J8*0%+K8*25%+L8*50%+M8*75%+N8*100%)/O8) -> 0
A9: 9c55cffff99073d4ebdef08e1a9c79a757143bf3ecc524033ef4ba8a53cdc5be | B9: =COUNTIF(รายงานลูกหนี้!$A:$A,A9) -> 8 | C9: =COUNTIFS(รายงานลูกหนี้!$A:$A,A9,รายงานลูกหนี้!$K:$K,">0") -> 6 | D9: =SUMIF(รายงานลูกหนี้!$A:$A,A9,รายงานลูกหนี้!$K:$K) -> 18 | E9: =_xlfn.MAXIFS(รายงานลูกหนี้!$K:$K,รายงานลูกหนี้!$A:$A,A9) -> 5 | F9: =C9/B9 -> 0.75 | G9: =IF(E9<=0, "ชำระตรงเวลา", IF(E9<=30, "ค้างชำระ 1 - 30 วัน", IF(E9<=60, "ค้างชำระ 31 - 60 วัน", IF(E9<=90, "ค้างชำระ 61 - 90 วัน", "ค้างชำระเกิน 90 วัน")))) -> ค้างชำระ 1 - 30 วัน | H9: =IF(E9<=30, "ลูกหนี้ชั้นดี", IF(E9<=90, "ลูกหนี้เฝ้าติดตาม", "ลูกหนี้ด้อยคุณภาพ (NPL)")) -> ลูกหนี้ชั้นดี | I9: {=_xlfn.IFS(D9=0,0%, D9<=30,25%, D9<=60,50%, D9<=90,75%, D9>90,100%)} -> 0.25 | J9: =SUMIFS(รายงานลูกหนี้!$G$2:$G$20000, รายงานลูกหนี้!$A$2:$A$20000, $A9, รายงานลูกหนี้!$K$2:$K$20000, 0) -> 3440 | K9: =SUMIFS(รายงานลูกหนี้!$G$2:$G$20000, รายงานลูกหนี้!$A$2:$A$20000, $A9, รายงานลูกหนี้!$K$2:$K$20000, ">=1", รายงานลูกหนี้!$K$2:$K$20000, "<=30") -> 13960 | L9: =SUMIFS(รายงานลูกหนี้!$G$2:$G$20000, รายงานลูกหนี้!$A$2:$A$20000, $A9, รายงานลูกหนี้!$K$2:$K$20000, ">=31", รายงานลูกหนี้!$K$2:$K$20000, "<=60") -> 0 | M9: =SUMIFS(รายงานลูกหนี้!$G$2:$G$20000, รายงานลูกหนี้!$A$2:$A$20000, $A9, รายงานลูกหนี้!$K$2:$K$20000, ">=61", รายงานลูกหนี้!$K$2:$K$20000, "<=90") -> 0 | N9: =SUMIFS(รายงานลูกหนี้!$G$2:$G$20000, รายงานลูกหนี้!$A$2:$A$20000, $A9, รายงานลูกหนี้!$K$2:$K$20000, ">90") -> 0 | O9: =SUM(J9:N9) -> 17400 | P9: =IF(O9=0, 0%, (J9*0%+K9*25%+L9*50%+M9*75%+N9*100%)/O9) -> 0.20057471
A10: 7914ce908cda19e741dd75c7b223b1857bf56c8de81c298d9da7eb0ed86efbb4 | B10: =COUNTIF(รายงานลูกหนี้!$A:$A,A10) -> 2 | C10: =COUNTIFS(รายงานลูกหนี้!$A:$A,A10,รายงานลูกหนี้!$K:$K,">0") -> 1 | D10: =SUMIF(รายงานลูกหนี้!$A:$A,A10,รายงานลูกหนี้!$K:$K) -> 2 | E10: =_xlfn.MAXIFS(รายงานลูกหนี้!$K:$K,รายงานลูกหนี้!$A:$A,A10) -> 2 | F10: =C10/B10 -> 0.5 | G10: =IF(E10<=0, "ชำระตรงเวลา", IF(E10<=30, "ค้างชำระ 1 - 30 วัน", IF(E10<=60, "ค้างชำระ 31 - 60 วัน", IF(E10<=90, "ค้างชำระ 61 - 90 วัน", "ค้างชำระเกิน 90 วัน")))) -> ค้างชำระ 1 - 30 วัน | H10: =IF(E10<=30, "ลูกหนี้ชั้นดี", IF(E10<=90, "ลูกหนี้เฝ้าติดตาม", "ลูกหนี้ด้อยคุณภาพ (NPL)")) -> ลูกหนี้ชั้นดี | I10: {=_xlfn.IFS(D10=0,0%, D10<=30,25%, D10<=60,50%, D10<=90,75%, D10>90,100%)} -> 0.25 | J10: =SUMIFS(รายงานลูกหนี้!$G$2:$G$20000, รายงานลูกหนี้!$A$2:$A$20000, $A10, รายงานลูกหนี้!$K$2:$K$20000, 0) -> 1850 | K10: =SUMIFS(รายงานลูกหนี้!$G$2:$G$20000, รายงานลูกหนี้!$A$2:$A$20000, $A10, รายงานลูกหนี้!$K$2:$K$20000, ">=1", รายงานลูกหนี้!$K$2:$K$20000, "<=30") -> 5220 | L10: =SUMIFS(รายงานลูกหนี้!$G$2:$G$20000, รายงานลูกหนี้!$A$2:$A$20000, $A10, รายงานลูกหนี้!$K$2:$K$20000, ">=31", รายงานลูกหนี้!$K$2:$K$20000, "<=60") -> 0 | M10: =SUMIFS(รายงานลูกหนี้!$G$2:$G$20000, รายงานลูกหนี้!$A$2:$A$20000, $A10, รายงานลูกหนี้!$K$2:$K$20000, ">=61", รายงานลูกหนี้!$K$2:$K$20000, "<=90") -> 0 | N10: =SUMIFS(รายงานลูกหนี้!$G$2:$G$20000, รายงานลูกหนี้!$A$2:$A$20000, $A10, รายงานลูกหนี้!$K$2:$K$20000, ">90") -> 0 | O10: =SUM(J10:N10) -> 7070 | P10: =IF(O10=0, 0%, (J10*0%+K10*25%+L10*50%+M10*75%+N10*100%)/O10) -> 0.18458274
A11: 53a194ee08d0adb2cdd9813398d0613159cccdae90786745f4a4bb8f4e755008 | B11: =COUNTIF(รายงานลูกหนี้!$A:$A,A11) -> 2 | C11: =COUNTIFS(รายงานลูกหนี้!$A:$A,A11,รายงานลูกหนี้!$K:$K,">0") -> 1 | D11: =SUMIF(รายงานลูกหนี้!$A:$A,A11,รายงานลูกหนี้!$K:$K) -> 2 | E11: =_xlfn.MAXIFS(รายงานลูกหนี้!$K:$K,รายงานลูกหนี้!$A:$A,A11) -> 2 | F11: =C11/B11 -> 0.5 | G11: =IF(E11<=0, "ชำระตรงเวลา", IF(E11<=30, "ค้างชำระ 1 - 30 วัน", IF(E11<=60, "ค้างชำระ 31 - 60 วัน", IF(E11<=90, "ค้างชำระ 61 - 90 วัน", "ค้างชำระเกิน 90 วัน")))) -> ค้างชำระ 1 - 30 วัน | H11: =IF(E11<=30, "ลูกหนี้ชั้นดี", IF(E11<=90, "ลูกหนี้เฝ้าติดตาม", "ลูกหนี้ด้อยคุณภาพ (NPL)")) -> ลูกหนี้ชั้นดี | I11: {=_xlfn.IFS(D11=0,0%, D11<=30,25%, D11<=60,50%, D11<=90,75%, D11>90,100%)} -> 0.25 | J11: =SUMIFS(รายงานลูกหนี้!$G$2:$G$20000, รายงานลูกหนี้!$A$2:$A$20000, $A11, รายงานลูกหนี้!$K$2:$K$20000, 0) -> 1610 | K11: =SUMIFS(รายงานลูกหนี้!$G$2:$G$20000, รายงานลูกหนี้!$A$2:$A$20000, $A11, รายงานลูกหนี้!$K$2:$K$20000, ">=1", รายงานลูกหนี้!$K$2:$K$20000, "<=30") -> 4454 | L11: =SUMIFS(รายงานลูกหนี้!$G$2:$G$20000, รายงานลูกหนี้!$A$2:$A$20000, $A11, รายงานลูกหนี้!$K$2:$K$20000, ">=31", รายงานลูกหนี้!$K$2:$K$20000, "<=60") -> 0 | M11: =SUMIFS(รายงานลูกหนี้!$G$2:$G$20000, รายงานลูกหนี้!$A$2:$A$20000, $A11, รายงานลูกหนี้!$K$2:$K$20000, ">=61", รายงานลูกหนี้!$K$2:$K$20000, "<=90") -> 0 | N11: =SUMIFS(รายงานลูกหนี้!$G$2:$G$20000, รายงานลูกหนี้!$A$2:$A$20000, $A11, รายงานลูกหนี้!$K$2:$K$20000, ">90") -> 0 | O11: =SUM(J11:N11) -> 6064 | P11: =IF(O11=0, 0%, (J11*0%+K11*25%+L11*50%+M11*75%+N11*100%)/O11) -> 0.18362467
A12: 562f700bd959ed5df49e26454a52c3b2b2b722eaa328ce19b2f9f36cc0cd5314 | B12: =COUNTIF(รายงานลูกหนี้!$A:$A,A12) -> 1 | C12: =COUNTIFS(รายงานลูกหนี้!$A:$A,A12,รายงานลูกหนี้!$K:$K,">0") -> 0 | D12: =SUMIF(รายงานลูกหนี้!$A:$A,A12,รายงานลูกหนี้!$K:$K) -> 0 | E12: =_xlfn.MAXIFS(รายงานลูกหนี้!$K:$K,รายงานลูกหนี้!$A:$A,A12) -> 0 | F12: =C12/B12 -> 0 | G12: =IF(E12<=0, "ชำระตรงเวลา", IF(E12<=30, "ค้างชำระ 1 - 30 วัน", IF(E12<=60, "ค้างชำระ 31 - 60 วัน", IF(E12<=90, "ค้างชำระ 61 - 90 วัน", "ค้างชำระเกิน 90 วัน")))) -> ชำระตรงเวลา | H12: =IF(E12<=30, "ลูกหนี้ชั้นดี", IF(E12<=90, "ลูกหนี้เฝ้าติดตาม", "ลูกหนี้ด้อยคุณภาพ (NPL)")) -> ลูกหนี้ชั้นดี | I12: {=_xlfn.IFS(D12=0,0%, D12<=30,25%, D12<=60,50%, D12<=90,75%, D12>90,100%)} -> 0 | J12: =SUMIFS(รายงานลูกหนี้!$G$2:$G$20000, รายงานลูกหนี้!$A$2:$A$20000, $A12, รายงานลูกหนี้!$K$2:$K$20000, 0) -> 506 | K12: =SUMIFS(รายงานลูกหนี้!$G$2:$G$20000, รายงานลูกหนี้!$A$2:$A$20000, $A12, รายงานลูกหนี้!$K$2:$K$20000, ">=1", รายงานลูกหนี้!$K$2:$K$20000, "<=30") -> 0 | L12: =SUMIFS(รายงานลูกหนี้!$G$2:$G$20000, รายงานลูกหนี้!$A$2:$A$20000, $A12, รายงานลูกหนี้!$K$2:$K$20000, ">=31", รายงานลูกหนี้!$K$2:$K$20000, "<=60") -> 0 | M12: =SUMIFS(รายงานลูกหนี้!$G$2:$G$20000, รายงานลูกหนี้!$A$2:$A$20000, $A12, รายงานลูกหนี้!$K$2:$K$20000, ">=61", รายงานลูกหนี้!$K$2:$K$20000, "<=90") -> 0 | N12: =SUMIFS(รายงานลูกหนี้!$G$2:$G$20000, รายงานลูกหนี้!$A$2:$A$20000, $A12, รายงานลูกหนี้!$K$2:$K$20000, ">90") -> 0 | O12: =SUM(J12:N12) -> 506 | P12: =IF(O12=0, 0%, (J12*0%+K12*25%+L12*50%+M12*75%+N12*100%)/O12) -> 0
A13: d624505038b4dc8617194229beac80401b936aca04d40978acdd1d72a56eb824 | B13: =COUNTIF(รายงานลูกหนี้!$A:$A,A13) -> 1 | C13: =COUNTIFS(รายงานลูกหนี้!$A:$A,A13,รายงานลูกหนี้!$K:$K,">0") -> 0 | D13: =SUMIF(รายงานลูกหนี้!$A:$A,A13,รายงานลูกหนี้!$K:$K) -> 0 | E13: =_xlfn.MAXIFS(รายงานลูกหนี้!$K:$K,รายงานลูกหนี้!$A:$A,A13) -> 0 | F13: =C13/B13 -> 0 | G13: =IF(E13<=0, "ชำระตรงเวลา", IF(E13<=30, "ค้างชำระ 1 - 30 วัน", IF(E13<=60, "ค้างชำระ 31 - 60 วัน", IF(E13<=90, "ค้างชำระ 61 - 90 วัน", "ค้างชำระเกิน 90 วัน")))) -> ชำระตรงเวลา | H13: =IF(E13<=30, "ลูกหนี้ชั้นดี", IF(E13<=90, "ลูกหนี้เฝ้าติดตาม", "ลูกหนี้ด้อยคุณภาพ (NPL)")) -> ลูกหนี้ชั้นดี | I13: {=_xlfn.IFS(D13=0,0%, D13<=30,25%, D13<=60,50%, D13<=90,75%, D13>90,100%)} -> 0 | J13: =SUMIFS(รายงานลูกหนี้!$G$2:$G$20000, รายงานลูกหนี้!$A$2:$A$20000, $A13, รายงานลูกหนี้!$K$2:$K$20000, 0) -> 5460 | K13: =SUMIFS(รายงานลูกหนี้!$G$2:$G$20000, รายงานลูกหนี้!$A$2:$A$20000, $A13, รายงานลูกหนี้!$K$2:$K$20000, ">=1", รายงานลูกหนี้!$K$2:$K$20000, "<=30") -> 0 | L13: =SUMIFS(รายงานลูกหนี้!$G$2:$G$20000, รายงานลูกหนี้!$A$2:$A$20000, $A13, รายงานลูกหนี้!$K$2:$K$20000, ">=31", รายงานลูกหนี้!$K$2:$K$20000, "<=60") -> 0 | M13: =SUMIFS(รายงานลูกหนี้!$G$2:$G$20000, รายงานลูกหนี้!$A$2:$A$20000, $A13, รายงานลูกหนี้!$K$2:$K$20000, ">=61", รายงานลูกหนี้!$K$2:$K$20000, "<=90") -> 0 | N13: =SUMIFS(รายงานลูกหนี้!$G$2:$G$20000, รายงานลูกหนี้!$A$2:$A$20000, $A13, รายงานลูกหนี้!$K$2:$K$20000, ">90") -> 0 | O13: =SUM(J13:N13) -> 5460 | P13: =IF(O13=0, 0%, (J13*0%+K13*25%+L13*50%+M13*75%+N13*100%)/O13) -> 0
A14: 5ef9356aa8a08dc3bfef8b0be13e9ebd2c9560518541939cea0fb1f4a7de9a81 | B14: =COUNTIF(รายงานลูกหนี้!$A:$A,A14) -> 4 | C14: =COUNTIFS(รายงานลูกหนี้!$A:$A,A14,รายงานลูกหนี้!$K:$K,">0") -> 4 | D14: =SUMIF(รายงานลูกหนี้!$A:$A,A14,รายงานลูกหนี้!$K:$K) -> 5 | E14: =_xlfn.MAXIFS(รายงานลูกหนี้!$K:$K,รายงานลูกหนี้!$A:$A,A14) -> 2 | F14: =C14/B14 -> 1 | G14: =IF(E14<=0, "ชำระตรงเวลา", IF(E14<=30, "ค้างชำระ 1 - 30 วัน", IF(E14<=60, "ค้างชำระ 31 - 60 วัน", IF(E14<=90, "ค้างชำระ 61 - 90 วัน", "ค้างชำระเกิน 90 วัน")))) -> ค้างชำระ 1 - 30 วัน | H14: =IF(E14<=30, "ลูกหนี้ชั้นดี", IF(E14<=90, "ลูกหนี้เฝ้าติดตาม", "ลูกหนี้ด้อยคุณภาพ (NPL)")) -> ลูกหนี้ชั้นดี | I14: {=_xlfn.IFS(D14=0,0%, D14<=30,25%, D14<=60,50%, D14<=90,75%, D14>90,100%)} -> 0.25 | J14: =SUMIFS(รายงานลูกหนี้!$G$2:$G$20000, รายงานลูกหนี้!$A$2:$A$20000, $A14, รายงานลูกหนี้!$K$2:$K$20000, 0) -> 0 | K14: =SUMIFS(รายงานลูกหนี้!$G$2:$G$20000, รายงานลูกหนี้!$A$2:$A$20000, $A14, รายงานลูกหนี้!$K$2:$K$20000, ">=1", รายงานลูกหนี้!$K$2:$K$20000, "<=30") -> 25605 | L14: =SUMIFS(รายงานลูกหนี้!$G$2:$G$20000, รายงานลูกหนี้!$A$2:$A$20000, $A14, รายงานลูกหนี้!$K$2:$K$20000, ">=31", รายงานลูกหนี้!$K$2:$K$20000, "<=60") -> 0 | M14: =SUMIFS(รายงานลูกหนี้!$G$2:$G$20000, รายงานลูกหนี้!$A$2:$A$20000, $A14, รายงานลูกหนี้!$K$2:$K$20000, ">=61", รายงานลูกหนี้!$K$2:$K$20000, "<=90") -> 0 | N14: =SUMIFS(รายงานลูกหนี้!$G$2:$G$20000, รายงานลูกหนี้!$A$2:$A$20000, $A14, รายงานลูกหนี้!$K$2:$K$20000, ">90") -> 0 | O14: =SUM(J14:N14) -> 25605 | P14: =IF(O14=0, 0%, (J14*0%+K14*25%+L14*50%+M14*75%+N14*100%)/O14) -> 0.25
... A3041: e35e5e3b17cda63210755c79819990388f2558ae | B3041: =COUNTIF(รายงานลูกหนี้!$A:$A,A3041) -> 16 | C3041: =COUNTIFS(รายงานลูกหนี้!$A:$A,A3041,รายงานลูกหนี้!$K:$K,">0") -> 0 | D3041: =SUMIF(รายงานลูกหนี้!$A:$A,A3041,รายงานลูกหนี้!$K:$K) -> 0 | E3041: =_xlfn.MAXIFS(รายงานลูกหนี้!$K:$K,รายงานลูกหนี้!$A:$A,A3041) -> 0 | F3041: =C3041/B3041 -> 0 | G3041: =IF(E3041<=0, "ชำระตรงเวลา", IF(E3041<=30, "ค้างชำระ 1 - 30 วัน", IF(E3041<=60, "ค้างชำระ 31 - 60 วัน", IF(E3041<=90, "ค้างชำระ 61 - 90 วัน", "ค้างชำระเกิน 90 วัน")))) -> ชำระตรงเวลา | H3041: =IF(E3041<=30, "ลูกหนี้ชั้นดี", IF(E3041<=90, "ลูกหนี้เฝ้าติดตาม", "ลูกหนี้ด้อยคุณภาพ (NPL)")) -> ลูกหนี้ชั้นดี | I3041: {=_xlfn.IFS(D3041=0,0%, D3041<=30,25%, D3041<=60,50%, D3041<=90,75%, D3041>90,100%)} -> 0 | J3041: =SUMIFS(รายงานลูกหนี้!$G$2:$G$20000, รายงานลูกหนี้!$A$2:$A$20000, $A3041, รายงานลูกหนี้!$K$2:$K$20000, 0) -> 155675 | K3041: =SUMIFS(รายงานลูกหนี้!$G$2:$G$20000, รายงานลูกหนี้!$A$2:$A$20000, $A3041, รายงานลูกหนี้!$K$2:$K$20000, ">=1", รายงานลูกหนี้!$K$2:$K$20000, "<=30") -> 0 | L3041: =SUMIFS(รายงานลูกหนี้!$G$2:$G$20000, รายงานลูกหนี้!$A$2:$A$20000, $A3041, รายงานลูกหนี้!$K$2:$K$20000, ">=31", รายงานลูกหนี้!$K$2:$K$20000, "<=60") -> 0 | M3041: =SUMIFS(รายงานลูกหนี้!$G$2:$G$20000, รายงานลูกหนี้!$A$2:$A$20000, $A3041, รายงานลูกหนี้!$K$2:$K$20000, ">=61", รายงานลูกหนี้!$K$2:$K$20000, "<=90") -> 0 | N3041: =SUMIFS(รายงานลูกหนี้!$G$2:$G$20000, รายงานลูกหนี้!$A$2:$A$20000, $A3041, รายงานลูกหนี้!$K$2:$K$20000, ">90") -> 0 | O3041: =SUM(J3041:N3041) -> 155675 | P3041: =IF(O3041=0, 0%, (J3041*0%+K3041*25%+L3041*50%+M3041*75%+N3041*100%)/O3041) -> 0

Sheet เงื่อนไข
A1: ตารางการวิเคราะห์อายุลูกหนี้ (Aging of Accounts Receivable)
A3: ชั้นลูกหนี้ | B3: ระยะเวลาค้างชำระ (Days Past Due) | C3: ความหมาย
A4: ชำระตรงเวลา (หรือยังไม่ถึงกำหนด) | B4: จำนวนวันค้างชำระ = 0 วัน | C4: ความเสี่ยงต่ำสุด ไม่ต้องตั้งค่าเผื่อหนี้สงสัยจะสูญ
A5: ค้างชำระ 1 - 30 วัน | B5: จำนวนวันค้างชำระ 1 ถึง 30 วัน | C5: ความเสี่ยงต่ำ ยังอยู่ในเกณฑ์ติดตามทวงถามได้ปกติ
A6: ค้างชำระ 31 - 60 วัน | B6: จำนวนวันค้างชำระ 31 ถึง 60 วัน | C6: ความเสี่ยงปานกลาง ควรเพิ่มความเข้มงวดในการติดตาม
A7: ค้างชำระ 61 - 90 วัน | B7: จำนวนวันค้างชำระ 61 ถึง 90 วัน | C7: ความเสี่ยงสูง อาจพิจารณาระงับการขายชั่วคราว
A8: ค้างชำระเกิน 90 วัน | B8: จำนวนวันค้างชำระตั้งแต่ 91 วันขึ้นไป | C8: ความเสี่ยงสูงมาก ถือเป็นหนี้ด้อยคุณภาพ (NPL) ควรพิจารณาตั้งค่าเผื่อหนี้สงสัยจะสูญ (Allowance for Doubtful Accounts) ในอัตราที่สูง
A10: หมายเหตุ : เกณฑ์การวิเคราะห์อายุลูกหนี้อ้างอิงตามแนวทาง Provision Matrix ของมาตรฐานการรายงานทางการเงิน TFRS 9 (เครื่องมือทางการเงิน)
A11: มาตรฐาน AR Aging (ประเมินอายุหนี้): ควรเพิ่มการทำรีพอร์ตสรุปตามช่วงวันค้างชำระ (1-30, 31-60, 61-90 วัน) เพื่อให้ฝ่ายบัญชีและการเงินเห็นภาพรวมของ "กระแสเงินสด" และสามารถตั้งค่าเผื่อหนี้สงสัยจะสูญ (Allowance for Doubtful Accounts) ได้ตามมาตรฐานการบัญชี
A13: ตารางเงื่อนไขการจัดชั้นลูกหนี้ (อ้างอิงมาตรฐาน TFRS 9)
A15: ชั้นลูกหนี้ | B15: เกณฑ์วันค้างชำระ | C15: ความหมาย
A16: ลูกหนี้ชั้นดี (Performing) | B16: ไม่ค้างชำระ หรือ ค้างชำระไม่เกิน 30 วัน | C16: ความเสี่ยงด้านเครดิตยังไม่เพิ่มขึ้น ถือเป็นลูกหนี้ปกติ
A17: ลูกหนี้เฝ้าติดตาม (Under-performing) | B17: ค้างชำระ 31 - 90 วัน | C17: ความเสี่ยงด้านเครดิตเพิ่มขึ้นอย่างมีนัยสำคัญ ควรเพิ่มความเข้มงวดในการติดตามทวงถาม
A18: ลูกหนี้ด้อยคุณภาพ (Non-performing / NPL) | B18: ค้างชำระเกิน 90 วันขึ้นไป | C18: ผิดนัดชำระและมีการด้อยค่าด้านเครดิต อาจต้องพิจารณาระงับการขายและตั้งสำรองหนี้สูญ
A20: หมายเหตุ : การแบ่งชั้นลูกหนี้และช่วงวันค้างชำระ (Days Past Due) อ้างอิงตามข้อสันนิษฐานของมาตรฐานการรายงานทางการเงิน TFRS 9 เรื่องเครื่องมือทางการเงิน (ย่อหน้า 5.5.11 และ B5.5.37) เพื่อนำไปใช้ประเมินความเสี่ยงและตั้งค่าเผื่อผลขาดทุนด้านเครดิตที่คาดว่าจะเกิดขึ้น (Expected Credit Loss)
